Workbook

Sheet Dashboard
A1: PM Technical Learning Dashboard
A3: Metric | B3: Value
A4: Total skills | B4: =COUNTA('Tech Roadmap'!$E$2:$E$200) -> 61
A5: Completed | B5: =COUNTIF('Tech Roadmap'!$L$2:$L$200,"Done") -> 0
A6: In Progress | B6: =COUNTIF('Tech Roadmap'!$L$2:$L$200,"In Progress") -> 0
A7: Not Started | B7: =COUNTIF('Tech Roadmap'!$L$2:$L$200,"Not Started") -> 61
A8: Skipped | B8: =COUNTIF('Tech Roadmap'!$L$2:$L$200,"Skipped") -> 0
A9: Overall Progress (weighted by weeks) | B9: =IFERROR(SUMPRODUCT('Tech Roadmap'!$J$2:$J$200,'Tech Roadmap'!$M$2:$M$200)/SUM('Tech Roadmap'!$J$2:$J$200),0) -> 0
A10: P0 skills completed | B10: =COUNTIFS('Tech Roadmap'!$I$2:$I$200,"P0",'Tech Roadmap'!$L$2:$L$200,"Done")&" of "&COUNTIF('Tech Roadmap'!$I$2:$I$200,"P0") -> 0 of 39
A11: Total planned weeks | B11: =SUM('Tech Roadmap'!$J$2:$J$200) -> 84
A12: Total planned hours | B12: =SUM('Tech Roadmap'!$K$2:$K$200) -> 294
A13: Hours spent so far | B13: =SUM('Tech Roadmap'!$N$2:$N$200) -> 0
A14: Remaining weeks (not Done/Skipped) | B14: =SUMIFS('Tech Roadmap'!$J$2:$J$200,'Tech Roadmap'!$L$2:$L$200,"<>Done",'Tech Roadmap'!$L$2:$L$200,"<>Skipped") -> 84
A15: Estimated finish date | B15: =IF('Study Plan'!$B$13="","Set start date in Study Plan",'Study Plan'!$B$13+B11*7) -> Set start date in Study Plan | C15: Assumes the Suggested Weeks pace at your Study Plan hours/week.
A18: Phase | B18: Skills | C18: Done | D18: Weeks | E18: Est. Hours | F18: Progress
A19: 1. Foundations | B19: =COUNTIF('Tech Roadmap'!$B$2:$B$200,A19) -> 15 | C19: =COUNTIFS('Tech Roadmap'!$B$2:$B$200,A19,'Tech Roadmap'!$L$2:$L$200,"Done") -> 0 | D19: =SUMIF('Tech Roadmap'!$B$2:$B$200,A19,'Tech Roadmap'!$J$2:$J$200) -> 16 | E19: =SUMIF('Tech Roadmap'!$B$2:$B$200,A19,'Tech Roadmap'!$K$2:$K$200) -> 56 | F19: =IFERROR(SUMPRODUCT(('Tech Roadmap'!$B$2:$B$200=A19)*'Tech Roadmap'!$J$2:$J$200*'Tech Roadmap'!$M$2:$M$200)/D19,0) -> 0
A20: 2. How Software Is Built | B20: =COUNTIF('Tech Roadmap'!$B$2:$B$200,A20) -> 9 | C20: =COUNTIFS('Tech Roadmap'!$B$2:$B$200,A20,'Tech Roadmap'!$L$2:$L$200,"Done") -> 0 | D20: =SUMIF('Tech Roadmap'!$B$2:$B$200,A20,'Tech Roadmap'!$J$2:$J$200) -> 11 | E20: =SUMIF('Tech Roadmap'!$B$2:$B$200,A20,'Tech Roadmap'!$K$2:$K$200) -> 38.5 | F20: =IFERROR(SUMPRODUCT(('Tech Roadmap'!$B$2:$B$200=A20)*'Tech Roadmap'!$J$2:$J$200*'Tech Roadmap'!$M$2:$M$200)/D20,0) -> 0
A21: 3. Cloud & Delivery | B21: =COUNTIF('Tech Roadmap'!$B$2:$B$200,A21) -> 10 | C21: =COUNTIFS('Tech Roadmap'!$B$2:$B$200,A21,'Tech Roadmap'!$L$2:$L$200,"Done") -> 0 | D21: =SUMIF('Tech Roadmap'!$B$2:$B$200,A21,'Tech Roadmap'!$J$2:$J$200) -> 12 | E21: =SUMIF('Tech Roadmap'!$B$2:$B$200,A21,'Tech Roadmap'!$K$2:$K$200) -> 42 | F21: =IFERROR(SUMPRODUCT(('Tech Roadmap'!$B$2:$B$200=A21)*'Tech Roadmap'!$J$2:$J$200*'Tech Roadmap'!$M$2:$M$200)/D21,0) -> 0
A22: 4. System Design | B22: =COUNTIF('Tech Roadmap'!$B$2:$B$200,A22) -> 6 | C22: =COUNTIFS('Tech Roadmap'!$B$2:$B$200,A22,'Tech Roadmap'!$L$2:$L$200,"Done") -> 0 | D22: =SUMIF('Tech Roadmap'!$B$2:$B$200,A22,'Tech Roadmap'!$J$2:$J$200) -> 7 | E22: =SUMIF('Tech Roadmap'!$B$2:$B$200,A22,'Tech Roadmap'!$K$2:$K$200) -> 24.5 | F22: =IFERROR(SUMPRODUCT(('Tech Roadmap'!$B$2:$B$200=A22)*'Tech Roadmap'!$J$2:$J$200*'Tech Roadmap'!$M$2:$M$200)/D22,0) -> 0
A23: 5. Data & Analytics | B23: =COUNTIF('Tech Roadmap'!$B$2:$B$200,A23) -> 5 | C23: =COUNTIFS('Tech Roadmap'!$B$2:$B$200,A23,'Tech Roadmap'!$L$2:$L$200,"Done") -> 0 | D23: =SUMIF('Tech Roadmap'!$B$2:$B$200,A23,'Tech Roadmap'!$J$2:$J$200) -> 9 | E23: =SUMIF('Tech Roadmap'!$B$2:$B$200,A23,'Tech Roadmap'!$K$2:$K$200) -> 31.5 | F23: =IFERROR(SUMPRODUCT(('Tech Roadmap'!$B$2:$B$200=A23)*'Tech Roadmap'!$J$2:$J$200*'Tech Roadmap'!$M$2:$M$200)/D23,0) -> 0
A24: 6. AI | B24: =COUNTIF('Tech Roadmap'!$B$2:$B$200,A24) -> 7 | C24: =COUNTIFS('Tech Roadmap'!$B$2:$B$200,A24,'Tech Roadmap'!$L$2:$L$200,"Done") -> 0 | D24: =SUMIF('Tech Roadmap'!$B$2:$B$200,A24,'Tech Roadmap'!$J$2:$J$200) -> 11 | E24: =SUMIF('Tech Roadmap'!$B$2:$B$200,A24,'Tech Roadmap'!$K$2:$K$200) -> 38.5 | F24: =IFERROR(SUMPRODUCT(('Tech Roadmap'!$B$2:$B$200=A24)*'Tech Roadmap'!$J$2:$J$200*'Tech Roadmap'!$M$2:$M$200)/D24,0) -> 0
A25: 7. Product + Tech | B25: =COUNTIF('Tech Roadmap'!$B$2:$B$200,A25) -> 5 | C25: =COUNTIFS('Tech Roadmap'!$B$2:$B$200,A25,'Tech Roadmap'!$L$2:$L$200,"Done") -> 0 | D25: =SUMIF('Tech Roadmap'!$B$2:$B$200,A25,'Tech Roadmap'!$J$2:$J$200) -> 7 | E25: =SUMIF('Tech Roadmap'!$B$2:$B$200,A25,'Tech Roadmap'!$K$2:$K$200) -> 24.5 | F25: =IFERROR(SUMPRODUCT(('Tech Roadmap'!$B$2:$B$200=A25)*'Tech Roadmap'!$J$2:$J$200*'Tech Roadmap'!$M$2:$M$200)/D25,0) -> 0
A26: 8. Capstone Portfolio | B26: =COUNTIF('Tech Roadmap'!$B$2:$B$200,A26) -> 4 | C26: =COUNTIFS('Tech Roadmap'!$B$2:$B$200,A26,'Tech Roadmap'!$L$2:$L$200,"Done") -> 0 | D26: =SUMIF('Tech Roadmap'!$B$2:$B$200,A26,'Tech Roadmap'!$J$2:$J$200) -> 11 | E26: =SUMIF('Tech Roadmap'!$B$2:$B$200,A26,'Tech Roadmap'!$K$2:$K$200) -> 38.5 | F26: =IFERROR(SUMPRODUCT(('Tech Roadmap'!$B$2:$B$200=A26)*'Tech Roadmap'!$J$2:$J$200*'Tech Roadmap'!$M$2:$M$200)/D26,0) -> 0

Sheet Tech Roadmap
A1: # | B1: Phase | C1: Category | D1: Topic | E1: Skill | F1: What to Learn | G1: Level | H1: Depth Needed | I1: Priority | J1: Suggested Weeks | K1: Est. Hours | L1: Status | M1: Progress % | N1: Hours Spent | O1: Start Date | P1: Completion Date | Q1: Proof of Learning | R1: Resources | S1: Notes
A2: 1 | B2: 1. Foundations | C2: Developer Tools | D2: Terminal | E2: Command line basics | F2: navigating folders, files, running commands, environment variables, package managers (pip, npm) | G2: Beginner | H2: Hands-on | I2: P0 | J2: 1 | K2: =J2*'Study Plan'!$B$12 -> 3.5 | L2: Not Started | M2: 0 | Q2: Create a project folder, install a package and run a script entirely from the terminal | S2: New topic added in review
A3: 2 | B3: 1. Foundations | C3: Developer Tools | D3: Git/GitHub | E3: Git fundamentals | F3: clone, add, commit, push, pull, branches, pull requests, merge conflicts | G3: Beginner | H3: Hands-on | I3: P0 | J3: 1 | K3: =J3*'Study Plan'!$B$12 -> 3.5 | L3: Not Started | M3: 0 | Q3: Push a repo to GitHub, open a pull request and merge it
A4: 3 | B4: 1. Foundations | C4: Developer Tools | D4: AI Tools | E4: AI coding assistants | F4: using Claude Code / Cursor / Copilot to read, explain and write code; reviewing AI output critically | G4: Beginner | H4: Hands-on | I4: P0 | J4: 1 | K4: =J4*'Study Plan'!$B$12 -> 3.5 | L4: Not Started | M4: 0 | Q4: Have an AI assistant explain an open-source repo and write a 1-page architecture summary | S4: New topic added in review
A5: 4 | B5: 1. Foundations | C5: Web Fundamentals | D5: HTTP | E5: How the web works | F5: HTTP/HTTPS, URLs, methods, status codes, headers, cookies, browser DevTools | G5: Beginner | H5: Conversant | I5: P0 | J5: 1 | K5: =J5*'Study Plan'!$B$12 -> 3.5 | L5: Not Started | M5: 0 | Q5: Inspect a website's network tab and explain 5 requests (method, status, payload)
A6: 5 | B6: 1. Foundations | C6: Web Fundamentals | D6: Networking | E6: Networking basics | F6: DNS, IP addresses, ports, what happens when you type a URL, CDN basics | G6: Beginner | H6: Conversant | I6: P1 | J6: 1 | K6: =J6*'Study Plan'!$B$12 -> 3.5 | L6: Not Started | M6: 0 | Q6: Explain end to end what happens when you open a URL | S6: New topic added in review
A7: 6 | B7: 1. Foundations | C7: Web Fundamentals | D7: APIs | E7: REST APIs | F7: endpoints, resources, requests/responses, JSON, using Postman | G7: Beginner | H7: Hands-on | I7: P0 | J7: 1 | K7: =J7*'Study Plan'!$B$12 -> 3.5 | L7: Not Started | M7: 0 | Q7: Call 3 public APIs in Postman (GET and POST)
A8: 7 | B8: 1. Foundations | C8: Web Fundamentals | D8: APIs | E8: API design for PMs | F8: versioning, pagination, rate limits, webhooks, idempotency, OpenAPI/Swagger docs | G8: Intermediate | H8: Conversant | I8: P1 | J8: 1 | K8: =J8*'Study Plan'!$B$12 -> 3.5 | L8: Not Started | M8: 0 | Q8: Read a public API doc (e.g. Stripe) and summarize its design choices | S8: New topic added in review
A9: 8 | B9: 1. Foundations | C9: Databases | D9: SQL | E9: SQL fundamentals | F9: SELECT, WHERE, GROUP BY, ORDER BY, aggregates | G9: Beginner | H9: Hands-on | I9: P0 | J9: 2 | K9: =J9*'Study Plan'!$B$12 -> 7 | L9: Not Started | M9: 0 | Q9: Solve 20 SQL exercises on a practice site
A10: 9 | B10: 1. Foundations | C10: Databases | D10: SQL | E10: Joins | F10: INNER, LEFT, relationships, multi-table queries | G10: Beginner | H10: Hands-on | I10: P0 | J10: 1 | K10: =J10*'Study Plan'!$B$12 -> 3.5 | L10: Not Started | M10: 0 | Q10: Write 10 join queries on a sample dataset
A11: 10 | B11: 1. Foundations | C11: Programming | D11: Python | E11: Core syntax | F11: variables, types, conditionals, loops, functions | G11: Beginner | H11: Hands-on | I11: P1 | J11: 1 | K11: =J11*'Study Plan'!$B$12 -> 3.5 | L11: Not Started | M11: 0 | Q11: Write 5 small functions (e.g. calculator, word counter)
A12: 11 | B12: 1. Foundations | C12: Programming | D12: Python | E12: Data structures | F12: lists, dicts, sets, tuples, comprehensions | G12: Beginner | H12: Hands-on | I12: P1 | J12: 1 | K12: =J12*'Study Plan'!$B$12 -> 3.5 | L12: Not Started | M12: 0 | Q12: Clean and summarize a small list of records with dicts
A13: 12 | B13: 1. Foundations | C13: Programming | D13: Python | E13: Error handling | F13: exceptions, debugging, basic testing | G13: Beginner | H13: Conversant | I13: P1 | J13: 1 | K13: =J13*'Study Plan'!$B$12 -> 3.5 | L13: Not Started | M13: 0 | Q13: Add try/except and 3 tests to an earlier script
A14: 13 | B14: 1. Foundations | C14: Programming | D14: Python | E14: Working with files & JSON | F14: read/write files, JSON, CSV | G14: Beginner | H14: Hands-on | I14: P1 | J14: 1 | K14: =J14*'Study Plan'!$B$12 -> 3.5 | L14: Not Started | M14: 0 | Q14: Convert a JSON file into a CSV
A15: 14 | B15: 1. Foundations | C15: Programming | D15: Python | E15: APIs with Python | F15: requests, GET/POST, parsing JSON responses | G15: Beginner | H15: Hands-on | I15: P0 | J15: 1 | K15: =J15*'Study Plan'!$B$12 -> 3.5 | L15: Not Started | M15: 0 | Q15: Script that calls a public API and saves results to CSV
A16: 15 | B16: 1. Foundations | C16: Portfolio | D16: Mini Project | E16: Mini project 1: API to insights | F16: Python pulls API data into SQLite, then answer 3 business questions with SQL | G16: Beginner | H16: Hands-on | I16: P0 | J16: 1 | K16: =J16*'Study Plan'!$B$12 -> 3.5 | L16: Not Started | M16: 0 | Q16: GitHub repo with README explaining the questions and answers | S16: New topic added in review
A17: 16 | B17: 2. How Software Is Built | C17: Engineering Process | D17: SDLC | E17: Software development lifecycle | F17: agile/scrum, sprints, environments (dev/staging/prod), release management, tech debt | G17: Beginner | H17: Conversant | I17: P0 | J17: 1 | K17: =J17*'Study Plan'!$B$12 -> 3.5 | L17: Not Started | M17: 0 | Q17: Map how a feature moves from idea to production at your company | S17: New topic added in review
A18: 17 | B18: 2. How Software Is Built | C18: Engineering Process | D18: Quality | E18: Testing & code review | F18: unit, integration, end-to-end tests, test pyramid, QA, code review etiquette | G18: Beginner | H18: Conversant | I18: P0 | J18: 1 | K18: =J18*'Study Plan'!$B$12 -> 3.5 | L18: Not Started | M18: 0 | Q18: Review a real pull request and list what you would test | S18: New topic added in review
A19: 18 | B19: 2. How Software Is Built | C19: Web Fundamentals | D19: Frontend | E19: Frontend concepts | F19: HTML/CSS/JS basics, browser rendering, React concepts, SPA vs SSR | G19: Beginner | H19: Conversant | I19: P1 | J19: 2 | K19: =J19*'Study Plan'!$B$12 -> 7 | L19: Not Started | M19: 0 | Q19: Build a 1-page HTML/JS form that calls an API
A20: 19 | B20: 2. How Software Is Built | C20: Backend | D20: Backend | E20: Server-side concepts | F20: services, routing, business logic, middleware, background jobs | G20: Intermediate | H20: Conversant | I20: P0 | J20: 1 | K20: =J20*'Study Plan'!$B$12 -> 3.5 | L20: Not Started | M20: 0 | Q20: Build a tiny API with 2 endpoints (FastAPI or Express)
A21: 20 | B21: 2. How Software Is Built | C21: Web Fundamentals | D21: Authentication | E21: Auth concepts | F21: sessions, tokens, JWT, OAuth/SSO basics, authentication vs authorization | G21: Intermediate | H21: Conversant | I21: P0 | J21: 1 | K21: =J21*'Study Plan'!$B$12 -> 3.5 | L21: Not Started | M21: 0 | Q21: Diagram the 'Login with Google' flow
A22: 21 | B22: 2. How Software Is Built | C22: Databases | D22: Databases | E22: Database fundamentals | F22: tables, keys, indexes, transactions, normalization, migrations | G22: Intermediate | H22: Conversant | I22: P0 | J22: 2 | K22: =J22*'Study Plan'!$B$12 -> 7 | L22: Not Started | M22: 0 | Q22: Design a schema for a simple product (users, orders, items)
A23: 22 | B23: 2. How Software Is Built | C23: Databases | D23: NoSQL/Cache | E23: NoSQL & caching | F23: MongoDB concepts, Redis, when to use each vs SQL | G23: Intermediate | H23: Aware | I23: P1 | J23: 1 | K23: =J23*'Study Plan'!$B$12 -> 3.5 | L23: Not Started | M23: 0 | Q23: Write a 1-paragraph SQL vs NoSQL decision for a sample feature
A24: 23 | B24: 2. How Software Is Built | C24: Backend | D24: Architecture | E24: Monolith vs microservices | F24: trade-offs, service boundaries, communication (REST, gRPC, events) | G24: Intermediate | H24: Conversant | I24: P1 | J24: 1 | K24: =J24*'Study Plan'!$B$12 -> 3.5 | L24: Not Started | M24: 0 | Q24: List pros/cons of splitting one service at your company
A25: 24 | B25: 2. How Software Is Built | C25: Web Fundamentals | D25: Mobile | E25: Mobile basics | F25: native vs cross-platform, app store review and release cycles, push notifications, offline | G25: Beginner | H25: Aware | I25: P2 | J25: 1 | K25: =J25*'Study Plan'!$B$12 -> 3.5 | L25: Not Started | M25: 0 | Q25: Compare release process of web vs mobile in 5 bullets | S25: New topic added in review
A26: 25 | B26: 3. Cloud & Delivery | C26: Cloud | D26: Cloud | E26: Cloud fundamentals | F26: compute, storage, networking, regions, availability zones, IaaS/PaaS/SaaS | G26: Beginner | H26: Conversant | I26: P0 | J26: 1 | K26: =J26*'Study Plan'!$B$12 -> 3.5 | L26: Not Started | M26: 0 | Q26: Explain IaaS vs PaaS vs SaaS with examples
A27: 26 | B27: 3. Cloud & Delivery | C27: Cloud | D27: AWS | E27: AWS fundamentals | F27: IAM, EC2, S3, RDS, Lambda, VPC basics, free tier | G27: Beginner | H27: Conversant | I27: P0 | J27: 2 | K27: =J27*'Study Plan'!$B$12 -> 7 | L27: Not Started | M27: 0 | Q27: Host a static site on S3 using the free tier
A28: 27 | B28: 3. Cloud & Delivery | C28: Cloud | D28: Containers | E28: Docker | F28: images, containers, Dockerfile, registries | G28: Beginner | H28: Conversant | I28: P1 | J28: 1 | K28: =J28*'Study Plan'!$B$12 -> 3.5 | L28: Not Started | M28: 0 | Q28: Containerize your mini project 1 script
A29: 28 | B29: 3. Cloud & Delivery | C29: Cloud | D29: CI/CD | E29: Deployment pipelines | F29: build, test, deploy, environments, rollback, GitHub Actions | G29: Intermediate | H29: Conversant | I29: P0 | J29: 1 | K29: =J29*'Study Plan'!$B$12 -> 3.5 | L29: Not Started | M29: 0 | Q29: Add a GitHub Actions workflow that runs tests
A30: 29 | B30: 3. Cloud & Delivery | C30: Cloud | D30: Releases | E30: Feature flags & rollouts | F30: feature flags, canary releases, blue/green, kill switches, progressive rollout | G30: Intermediate | H30: Conversant | I30: P0 | J30: 1 | K30: =J30*'Study Plan'!$B$12 -> 3.5 | L30: Not Started | M30: 0 | Q30: Write a rollout plan for a risky feature | S30: New topic added in review
A31: 30 | B31: 3. Cloud & Delivery | C31: Cloud | D31: Kubernetes | E31: Kubernetes concepts | F31: pods, deployments, services, ingress, scaling (awareness only) | G31: Intermediate | H31: Aware | I31: P2 | J31: 1 | K31: =J31*'Study Plan'!$B$12 -> 3.5 | L31: Not Started | M31: 0 | Q31: Explain what Kubernetes solves in 5 sentences
A32: 31 | B32: 3. Cloud & Delivery | C32: Operations | D32: Observability | E32: Observability | F32: logs, metrics, traces, dashboards, alerting, SLIs/SLOs/SLAs | G32: Intermediate | H32: Conversant | I32: P0 | J32: 1 | K32: =J32*'Study Plan'!$B$12 -> 3.5 | L32: Not Started | M32: 0 | Q32: Define 3 SLOs for a product you use | S32: New topic added in review
A33: 32 | B33: 3. Cloud & Delivery | C33: Operations | D33: Incidents | E33: Incident management | F33: on-call, severity levels, incident response, blameless postmortems | G33: Intermediate | H33: Conversant | I33: P1 | J33: 1 | K33: =J33*'Study Plan'!$B$12 -> 3.5 | L33: Not Started | M33: 0 | Q33: Read 2 public postmortems and summarize lessons | S33: New topic added in review
A34: 33 | B34: 3. Cloud & Delivery | C34: Operations | D34: Security | E34: Security & privacy basics | F34: OWASP Top 10 (high level), encryption at rest/in transit, secrets, RBAC, PII, GDPR | G34: Intermediate | H34: Conversant | I34: P0 | J34: 2 | K34: =J34*'Study Plan'!$B$12 -> 7 | L34: Not Started | M34: 0 | Q34: Write a security/privacy checklist for a new feature | S34: New topic added in review
A35: 34 | B35: 3. Cloud & Delivery | C35: Cloud | D35: Cost | E35: Cloud cost & FinOps | F35: pricing models, what drives the bill, on-demand vs reserved, cost per user | G35: Intermediate | H35: Aware | I35: P1 | J35: 1 | K35: =J35*'Study Plan'!$B$12 -> 3.5 | L35: Not Started | M35: 0 | Q35: Estimate monthly AWS cost for a simple app with the AWS calculator | S35: New topic added in review
A36: 35 | B36: 4. System Design | C36: System Design | D36: Architecture | E36: System design basics | F36: requirements, components, data flow, trade-offs | G36: Intermediate | H36: Conversant | I36: P0 | J36: 2 | K36: =J36*'Study Plan'!$B$12 -> 7 | L36: Not Started | M36: 0 | Q36: Draw an architecture diagram of a product you use
A37: 36 | B37: 4. System Design | C37: System Design | D37: Scalability | E37: Scaling systems | F37: horizontal/vertical scaling, load balancing, stateless services | G37: Intermediate | H37: Conversant | I37: P1 | J37: 1 | K37: =J37*'Study Plan'!$B$12 -> 3.5 | L37: Not Started | M37: 0 | Q37: Explain how you'd handle 10x traffic for a sample app
A38: 37 | B38: 4. System Design | C38: System Design | D38: Performance | E38: Caching & latency | F38: CDNs, caching layers, latency, bottlenecks | G38: Intermediate | H38: Conversant | I38: P1 | J38: 1 | K38: =J38*'Study Plan'!$B$12 -> 3.5 | L38: Not Started | M38: 0 | Q38: Identify 3 caching opportunities in your diagram
A39: 38 | B39: 4. System Design | C39: System Design | D39: Reliability | E39: Reliability concepts | F39: availability, fault tolerance, redundancy, backups, disaster recovery | G39: Intermediate | H39: Conversant | I39: P1 | J39: 1 | K39: =J39*'Study Plan'!$B$12 -> 3.5 | L39: Not Started | M39: 0 | Q39: Write a failure-mode list for your diagram
A40: 39 | B40: 4. System Design | C40: System Design | D40: Async Systems | E40: Queues & events | F40: message queues, event-driven architecture, workers, retries | G40: Intermediate | H40: Conversant | I40: P1 | J40: 1 | K40: =J40*'Study Plan'!$B$12 -> 3.5 | L40: Not Started | M40: 0 | Q40: Redesign one sync flow as async and list trade-offs
...

Sheet Study Plan
A1: Item | B1: Recommendation
A2: Weekly plan | B2: Recommended while studying GMAT
A3: GMAT | B3: 10–12 hrs/week
A4: Technical learning | B4: 3–4 hrs/week
A5: PM/product practice | B5: 1 hr/week
A6: Rule | B6: Keep tech consistent; increase intensity after GMAT
A7: Priority | B7: Learn breadth first; don't try to become a full-stack engineer
A8: Order | B8: Follow the # column in Tech Roadmap; P0 skills first if short on time
A9: Practice | B9: Finish each skill's Proof of Learning before marking it Done
A11: Inputs (edit yellow cells)
A12: Tech hours per week | B12: 3.5 | C12: Midpoint of your 3–4 hrs/week. Drives Est. Hours and finish date.
A13: Plan start date | C13: Enter the date you start Phase 1.
A14: GMAT exam date | C14: Enter your exam date; plan to raise tech hours after it.
A15: Tech hours per week after GMAT | B15: 7 | C15: Assumption: roughly double once GMAT is done. Change as needed.

Sheet Guide
A1: Column / Term | B1: Meaning
A2: How to use | B2: Work top to bottom by #. Update Status, Progress % and Hours Spent in Tech Roadmap; Dashboard updates itself.
A3: Editable cells | B3: Tech Roadmap: Status, Progress %, Hours Spent, Start/Completion Date, Resources, Notes. Study Plan: yellow input cells.
A4: Depth: Aware | B4: Know what it is and why it matters; can follow an engineering conversation.
A5: Depth: Conversant | B5: Can explain it, ask good questions, and reason about trade-offs.
A6: Depth: Hands-on | B6: Can actually do it yourself (write the query, call the API, build the prototype).
A7: Priority: P0 | B7: Core for any technical PM. Do not skip.
A8: Priority: P1 | B8: Important; do after P0 skills in the same phase.
A9: Priority: P2 | B9: Nice to have; skip or skim if short on time, or if your future niche does not need it.
A10: Suggested Weeks | B10: Calendar weeks at the Study Plan tech hours/week.
A11: Est. Hours | B11: Suggested Weeks x Study Plan 'Tech hours per week'.
A12: Proof of Learning | B12: A small output that shows you can apply the skill. Finish it before marking Done.
... A15: Niche later | B15: After Phase 7, pick a direction (AI PM, Platform/API PM, Data PM, Growth PM) and add a deeper phase for it.
